Workbook

Sheet מקרא
A1: קובץ איתור חוות ומשקים — דרום הארץ
A2: פרויקט לא ינום · עמותת ארצנו
A4: מבנה הקובץ — שורה אחת לכל חווה, לא לכל יישוב
A5: ביישוב אחד יכולים לפעול כמה חקלאים עצמאיים, כל אחד עם השטחים וההסכם שלו.
A6: להוספת חווה נוספת באותו יישוב: לשכפל את השורה ולשנות שם החווה ושם החקלאי.
A7: עמודות היישוב (יישוב, סמל, מועצה, קואורדינטות) נשארות זהות בשכפול.
A9: מקדם שקלול
A10: מקדם לשטח מעובד | B10: 1
A11: מקדם לשטח מרעה | B11: 0.02
A12: (יחס 1:50 — כל 50 דונם מרעה נספרים כדונם אחד)
A14: יעד
A15: יעד דונם משוקלל | B15: 100000
A16: נאסף עד כה | B16: =SUM(רשימה!V2:V800) -> 0
A17: אחוז מהיעד | B17: =IFERROR(B16/B15,0) -> 0
A19: צבעי העמודות
A20: כחול | B20: זהות החווה — שם החווה ושם החקלאי. אלה שדות המפתח.
A21: צהוב | B21: למילוי ידני בשטח.
A22: ירוק | B22: מחושב אוטומטית — לא לגעת.
A23: כתום | B23: הערכת סדר גודל ליישוב כולו, לא לחווה. אינה נתון רשמי.
A24: לבן | B24: נתוני יישוב מאומתים מהלמ״ס — שם, סמל, מועצה, קואורדינטות.
A26: שם המקום
A27: נבנה אוטומטית בתבנית של העמותה:
A28: שם החווה + שם החקלאי | B28: חוות ארץ השמש - החווה של עשהאל קורניץ
A29: רק שם החקלאי | B29: החווה של אביה לינגר
A30: אף אחד מהם | B30: שם היישוב, עד שיתמלא
A32: סוגי הסכמי קרקע
A33: חוזה חכירה לדורות | B33: הזכות החזקה. 4 תקופות מתחדשות של 49 שנה. רמ״י.
A34: חוזה שכירות משבצת (תלת-צדדי) | B34: רמ״י + הסוכנות + האגודה. מתחדש כל 3 שנים.
A35: הסכם הרשאה לרעייה | B35: בר-רשות בלבד. זכות חלשה, קצובה, לא עבירה ולא ניתנת להורשה.
A36: הצהרת חקלאים בלבד | B36: אינו מסמך זכויות. לא מספיק לאימות הבעלות על הקרקע.
A38: מקורות
A39: רשימות יישובים וטלפוני מועצות | B39: mhh.org.il/maparea
A40: סמל יישוב וקואורדינטות | B40: קובץ היישובים של הלמ״ס 2021

Sheet רשימה
A1: מס' | B1: שם המקום (כפי שיישלח אליהם) | C1: שם החווה | D1: שם החקלאי | E1: נייד החקלאי | F1: מייל חקלאי | G1: סוג הישות המשפטית | H1: ארגון מאגד (אגודה/גד״ש/שח״ם) | I1: יישוב | J1: סמל יישוב (למ״ס) | K1: סוג יישוב | L1: מועצה אזורית | M1: אזור (באפליקציה) | N1: טלפון מרכזיית המועצה | O1: איש קשר (מועצה/אגודה) | P1: נייד — איש קשר | Q1: סוג פעילות | R1: אומדן ליישוב כולו (דונם) — הערכה | S1: שטח מעובד (דונם) | T1: שטח מרעה (דונם) | U1: שטחים שמירה (דונם) | V1: דונם משוקלל | W1: הסכם רעיה/חכירה | X1: תאריך תפוגה הסכם קרקע | Y1: כמות מתנדבים קבועים | Z1: סטטוס | AA1: עדיפות (1-3) | AB1: קו רוחב | AC1: קו אורך | AD1: Google Maps | AE1: Waze | AF1: הערות
A2: 1 | B2: =IF(C2="",IF(D2="",I2,"החווה של "&D2),IF(D2="",C2,C2&" - החווה של "&D2)) -> טללים | I2: טללים | J2: 1177 | K2: קיבוץ | L2: רמת הנגב | M2: הנגב | N2: 08-6564111 | R2: 9000 | V2: =IF(AND(S2="",T2=""),"",IFERROR(N(S2)*מקרא!$B$10+N(T2)*מקרא!$B$11,"")) | AB2: 30.99206 | AC2: 34.76999 | AD2: מפה | AE2: Waze
A3: 2 | B3: =IF(C3="",IF(D3="",I3,"החווה של "&D3),IF(D3="",C3,C3&" - החווה של "&D3)) -> משאבי שדה | I3: משאבי שדה | J3: 421 | K3: קיבוץ | L3: רמת הנגב | M3: הנגב | N3: 08-6564111 | R3: 9000 | V3: =IF(AND(S3="",T3=""),"",IFERROR(N(S3)*מקרא!$B$10+N(T3)*מקרא!$B$11,"")) | AB3: 31.00321 | AC3: 34.78617 | AD3: מפה | AE3: Waze
A4: 3 | B4: =IF(C4="",IF(D4="",I4,"החווה של "&D4),IF(D4="",C4,C4&" - החווה של "&D4)) -> רביבים | I4: רביבים | J4: 354 | K4: קיבוץ | L4: רמת הנגב | M4: הנגב | N4: 08-6564111 | R4: 9000 | V4: =IF(AND(S4="",T4=""),"",IFERROR(N(S4)*מקרא!$B$10+N(T4)*מקרא!$B$11,"")) | AB4: 31.04393 | AC4: 34.72177 | AD4: מפה | AE4: Waze
A5: 4 | B5: =IF(C5="",IF(D5="",I5,"החווה של "&D5),IF(D5="",C5,C5&" - החווה של "&D5)) -> רתמים | I5: רתמים | J5: 1260 | K5: קיבוץ | L5: רמת הנגב | M5: הנגב | N5: 08-6564111 | R5: 9000 | V5: =IF(AND(S5="",T5=""),"",IFERROR(N(S5)*מקרא!$B$10+N(T5)*מקרא!$B$11,"")) | AB5: 31.05373 | AC5: 34.68967 | AD5: מפה | AE5: Waze
A6: 5 | B6: =IF(C6="",IF(D6="",I6,"החווה של "&D6),IF(D6="",C6,C6&" - החווה של "&D6)) -> שדה בוקר | I6: שדה בוקר | J6: 885 | K6: קיבוץ | L6: רמת הנגב | M6: הנגב | N6: 08-6564111 | R6: 9000 | V6: =IF(AND(S6="",T6=""),"",IFERROR(N(S6)*מקרא!$B$10+N(T6)*מקרא!$B$11,"")) | AB6: 30.87326 | AC6: 34.79311 | AD6: מפה | AE6: Waze
A7: 6 | B7: =IF(C7="",IF(D7="",I7,"החווה של "&D7),IF(D7="",C7,C7&" - החווה של "&D7)) -> כמהין | I7: כמהין | J7: 1291 | K7: מושב | L7: רמת הנגב | M7: הנגב | N7: 08-6564111 | R7: 3250 | V7: =IF(AND(S7="",T7=""),"",IFERROR(N(S7)*מקרא!$B$10+N(T7)*מקרא!$B$11,"")) | AB7: 30.91066 | AC7: 34.43143 | AD7: מפה | AE7: Waze
A8: 7 | B8: =IF(C8="",IF(D8="",I8,"החווה של "&D8),IF(D8="",C8,C8&" - החווה של "&D8)) -> קדש ברנע | I8: קדש ברנע | K8: מושב | L8: רמת הנגב | M8: הנגב | N8: 08-6564111 | R8: 3250 | V8: =IF(AND(S8="",T8=""),"",IFERROR(N(S8)*מקרא!$B$10+N(T8)*מקרא!$B$11,"")) | AD8: מפה | AE8: Waze
A9: 8 | B9: =IF(C9="",IF(D9="",I9,"החווה של "&D9),IF(D9="",C9,C9&" - החווה של "&D9)) -> עזוז | I9: עזוז | J9: 328 | K9: יישוב קהילתי | L9: רמת הנגב | M9: הנגב | N9: 08-6564111 | R9: 700 | V9: =IF(AND(S9="",T9=""),"",IFERROR(N(S9)*מקרא!$B$10+N(T9)*מקרא!$B$11,"")) | AB9: 30.7923 | AC9: 34.47271 | AD9: מפה | AE9: Waze
A10: 9 | B10: =IF(C10="",IF(D10="",I10,"החווה של "&D10),IF(D10="",C10,C10&" - החווה של "&D10)) -> אשלים | I10: אשלים | J10: 1152 | K10: יישוב קהילתי | L10: רמת הנגב | M10: הנגב | N10: 08-6564111 | R10: 700 | V10: =IF(AND(S10="",T10=""),"",IFERROR(N(S10)*מקרא!$B$10+N(T10)*מקרא!$B$11,"")) | AB10: 30.96448 | AC10: 34.69999 | AD10: מפה | AE10: Waze
A11: 10 | B11: =IF(C11="",IF(D11="",I11,"החווה של "&D11),IF(D11="",C11,C11&" - החווה של "&D11)) -> חוות בודדים — רמת נגב (כ-23 חוות) | I11: חוות בודדים — רמת נגב (כ-23 חוות) | K11: חוות בודדים | L11: רמת הנגב | M11: הנגב | N11: 08-6564111 | R11: 17500 | V11: =IF(AND(S11="",T11=""),"",IFERROR(N(S11)*מקרא!$B$10+N(T11)*מקרא!$B$11,"")) | AD11: מפה | AE11: Waze | AF11: לבקש את הרשימה השמית מהמועצה — פוטנציאל מרעה גדול
A12: 11 | B12: =IF(C12="",IF(D12="",I12,"החווה של "&D12),IF(D12="",C12,C12&" - החווה של "&D12)) -> אורים | I12: אורים | J12: 403 | K12: קיבוץ | L12: אשכול | M12: הנגב | N12: 08-9929111 | R12: 9000 | V12: =IF(AND(S12="",T12=""),"",IFERROR(N(S12)*מקרא!$B$10+N(T12)*מקרא!$B$11,"")) | AB12: 31.30413 | AC12: 34.52256 | AD12: מפה | AE12: Waze | AF12: מועצת עוטף עזה
A13: 12 | B13: =IF(C13="",IF(D13="",I13,"החווה של "&D13),IF(D13="",C13,C13&" - החווה של "&D13)) -> בארי | I13: בארי | J13: 399 | K13: קיבוץ | L13: אשכול | M13: הנגב | N13: 08-9929111 | R13: 9000 | V13: =IF(AND(S13="",T13=""),"",IFERROR(N(S13)*מקרא!$B$10+N(T13)*מקרא!$B$11,"")) | AB13: 31.42382 | AC13: 34.49078 | AD13: מפה | AE13: Waze | AF13: מועצת עוטף עזה
A14: 13 | B14: =IF(C14="",IF(D14="",I14,"החווה של "&D14),IF(D14="",C14,C14&" - החווה של "&D14)) -> גבולות | I14: גבולות | J14: 352 | K14: קיבוץ | L14: אשכול | M14: הנגב | N14: 08-9929111 | R14: 9000 | V14: =IF(AND(S14="",T14=""),"",IFERROR(N(S14)*מקרא!$B$10+N(T14)*מקרא!$B$11,"")) | AB14: 31.21083 | AC14: 34.46541 | AD14: מפה | AE14: Waze | AF14: מועצת עוטף עזה
A15: 14 | B15: =IF(C15="",IF(D15="",I15,"החווה של "&D15),IF(D15="",C15,C15&" - החווה של "&D15)) -> חולית | I15: חולית | J15: 1239 | K15: קיבוץ | L15: אשכול | M15: הנגב | N15: 08-9929111 | R15: 9000 | V15: =IF(AND(S15="",T15=""),"",IFERROR(N(S15)*מקרא!$B$10+N(T15)*מקרא!$B$11,"")) | AB15: 31.23061 | AC15: 34.32567 | AD15: מפה | AE15: Waze | AF15: מועצת עוטף עזה
A16: 15 | B16: =IF(C16="",IF(D16="",I16,"החווה של "&D16),IF(D16="",C16,C16&" - החווה של "&D16)) -> כיסופים | I16: כיסופים | J16: 840 | K16: קיבוץ | L16: אשכול | M16: הנגב | N16: 08-9929111 | R16: 9000 | V16: =IF(AND(S16="",T16=""),"",IFERROR(N(S16)*מקרא!$B$10+N(T16)*מקרא!$B$11,"")) | AB16: 31.37521 | AC16: 34.39906 | AD16: מפה | AE16: Waze | AF16: מועצת עוטף עזה
A17: 16 | B17: =IF(C17="",IF(D17="",I17,"החווה של "&D17),IF(D17="",C17,C17&" - החווה של "&D17)) -> כרם שלום | I17: כרם שלום | J17: 1085 | K17: קיבוץ | L17: אשכול | M17: הנגב | N17: 08-9929111 | R17: 9000 | V17: =IF(AND(S17="",T17=""),"",IFERROR(N(S17)*מקרא!$B$10+N(T17)*מקרא!$B$11,"")) | AB17: 31.2277 | AC17: 34.28424 | AD17: מפה | AE17: Waze | AF17: מועצת עוטף עזה
A18: 17 | B18: =IF(C18="",IF(D18="",I18,"החווה של "&D18),IF(D18="",C18,C18&" - החווה של "&D18)) -> מגן | I18: מגן | J18: 695 | K18: קיבוץ | L18: אשכול | M18: הנגב | N18: 08-9929111 | R18: 9000 | V18: =IF(AND(S18="",T18=""),"",IFERROR(N(S18)*מקרא!$B$10+N(T18)*מקרא!$B$11,"")) | AB18: 31.29971 | AC18: 34.42691 | AD18: מפה | AE18: Waze | AF18: מועצת עוטף עזה
A19: 18 | B19: =IF(C19="",IF(D19="",I19,"החווה של "&D19),IF(D19="",C19,C19&" - החווה של "&D19)) -> ניר יצחק | I19: ניר יצחק | J19: 402 | K19: קיבוץ | L19: אשכול | M19: הנגב | N19: 08-9929111 | R19: 9000 | V19: =IF(AND(S19="",T19=""),"",IFERROR(N(S19)*מקרא!$B$10+N(T19)*מקרא!$B$11,"")) | AB19: 31.23768 | AC19: 34.35762 | AD19: מפה | AE19: Waze | AF19: מועצת עוטף עזה
A20: 19 | B20: =IF(C20="",IF(D20="",I20,"החווה של "&D20),IF(D20="",C20,C20&" - החווה של "&D20)) -> ניר עוז | I20: ניר עוז | J20: 69 | K20: קיבוץ | L20: אשכול | M20: הנגב | N20: 08-9929111 | R20: 9000 | V20: =IF(AND(S20="",T20=""),"",IFERROR(N(S20)*מקרא!$B$10+N(T20)*מקרא!$B$11,"")) | AB20: 31.31074 | AC20: 34.40171 | AD20: מפה | AE20: Waze | AF20: מועצת עוטף עזה
A21: 20 | B21: =IF(C21="",IF(D21="",I21,"החווה של "&D21),IF(D21="",C21,C21&" - החווה של "&D21)) -> נירים | I21: נירים | J21: 602 | K21: קיבוץ | L21: אשכול | M21: הנגב | N21: 08-9929111 | R21: 9000 | V21: =IF(AND(S21="",T21=""),"",IFERROR(N(S21)*מקרא!$B$10+N(T21)*מקרא!$B$11,"")) | AB21: 31.33595 | AC21: 34.39488 | AD21: מפה | AE21: Waze | AF21: מועצת עוטף עזה
A22: 21 | B22: =IF(C22="",IF(D22="",I22,"החווה של "&D22),IF(D22="",C22,C22&" - החווה של "&D22)) -> סופה | I22: סופה | J22: 1238 | K22: קיבוץ | L22: אשכול | M22: הנגב | N22: 08-9929111 | R22: 9000 | V22: =IF(AND(S22="",T22=""),"",IFERROR(N(S22)*מקרא!$B$10+N(T22)*מקרא!$B$11,"")) | AB22: 31.2373 | AC22: 34.34209 | AD22: מפה | AE22: Waze | AF22: מועצת עוטף עזה
A23: 22 | B23: =IF(C23="",IF(D23="",I23,"החווה של "&D23),IF(D23="",C23,C23&" - החווה של "&D23)) -> עין השלושה | I23: עין השלושה | J23: 676 | K23: קיבוץ | L23: אשכול | M23: הנגב | N23: 08-9929111 | R23: 9000 | V23: =IF(AND(S23="",T23=""),"",IFERROR(N(S23)*מקרא!$B$10+N(T23)*מקרא!$B$11,"")) | AB23: 31.35141 | AC23: 34.40158 | AD23: מפה | AE23: Waze | AF23: מועצת עוטף עזה
... A43: 42 | B43: =IF(C43="",IF(D43="",I43,"החווה של "&D43),IF(D43="",C43,C43&" - החווה של "&D43)) -> אבשלום | I43: אבשלום | J43: 1311 | K43: יישוב קהילתי | L43: אשכול | M43: הנגב | N43: 08-9929111 | R43: 700 | V43: =IF(AND(S43="",T43=""),"",IFERROR(N(S43)*מקרא!$B$10+N(T43)*מקרא!$B$11,"")) | AB43: 31.19556 | AC43: 34.33082 | AD43: מפה | AE43: Waze | AF43: מועצת עוטף עזה
A44: 43 | B44: =IF(C44="",IF(D44="",I44,"החווה של "&D44),IF(D44="",C44,C44&" - החווה של "&D44)) -> אשבול | I44: אשבול | J44: 71 | K44: מושב | L44: מרחבים | M44: הנגב | N44: 08-9929444 | R44: 3250 | V44: =IF(AND(S44="",T44=""),"",IFERROR(N(S44)*מקרא!$B$10+N(T44)*מקרא!$B$11,"")) | AB44: 31.44749 | AC44: 34.66596 | AD44: מפה | AE44: Waze
A45: 44 | B45: =IF(C45="",IF(D45="",I45,"החווה של "&D45),IF(D45="",C45,C45&" - החווה של "&D45)) -> בטחה | I45: בטחה | J45: 762 | K45: מושב | L45: מרחבים | M45: הנגב | N45: 08-9929444 | R45: 3250 | V45: =IF(AND(S45="",T45=""),"",IFERROR(N(S45)*מקרא!$B$10+N(T45)*מקרא!$B$11,"")) | AB45: 31.33425 | AC45: 34.63246 | AD45: מפה | AE45: Waze
A46: 45 | B46: =IF(C46="",IF(D46="",I46,"החווה של "&D46),IF(D46="",C46,C46&" - החווה של "&D46)) -> גילת | I46: גילת | J46: 736 | K46: מושב | L46: מרחבים | M46: הנגב | N46: 08-9929444 | R46: 3250 | V46: =IF(AND(S46="",T46=""),"",IFERROR(N(S46)*מקרא!$B$10+N(T46)*מקרא!$B$11,"")) | AB46: 31.32793 | AC46: 34.65193 | AD46: מפה | AE46: Waze
A47: 46 | B47: =IF(C47="",IF(D47="",I47,"החווה של "&D47),IF(D47="",C47,C47&" - החווה של "&D47)) -> מסלול | I47: מסלול | J47: 748 | K47: מושב | L47: מרחבים | M47: הנגב | N47: 08-9929444 | R47: 3250 | V47: =IF(AND(S47="",T47=""),"",IFERROR(N(S47)*מקרא!$B$10+N(T47)*מקרא!$B$11,"")) | AB47: 31.32431 | AC47: 34.58944 | AD47: מפה | AE47: Waze
A48: 47 | B48: =IF(C48="",IF(D48="",I48,"החווה של "&D48),IF(D48="",C48,C48&" - החווה של "&D48)) -> ניר משה | I48: ניר משה | J48: 2047 | K48: מושב | L48: מרחבים | M48: הנגב | N48: 08-9929444 | R48: 3250 | V48: =IF(AND(S48="",T48=""),"",IFERROR(N(S48)*מקרא!$B$10+N(T48)*מקרא!$B$11,"")) | AB48: 31.47746 | AC48: 34.63085 | AD48: מפה | AE48: Waze
A49: 48 | B49: =IF(C49="",IF(D49="",I49,"החווה של "&D49),IF(D49="",C49,C49&" - החווה של "&D49)) -> ניר עקיבא | I49: ניר עקיבא | J49: 2048 | K49: מושב | L49: מרחבים | M49: הנגב | N49: 08-9929444 | R49: 3250 | V49: =IF(AND(S49="",T49=""),"",IFERROR(N(S49)*מקרא!$B$10+N(T49)*מקרא!$B$11,"")) | AB49: 31.46987 | AC49: 34.64658 | AD49: מפה | AE49: Waze
A50: 49 | B50: =IF(C50="",IF(D50="",I50,"החווה של "&D50),IF(D50="",C50,C50&" - החווה של "&D50)) -> פדויים | I50: פדויים | J50: 750 | K50: מושב | L50: מרחבים | M50: הנגב | N50: 08-9929444 | R50: 3250 | V50: =IF(AND(S50="",T50=""),"",IFERROR(N(S50)*מקרא!$B$10+N(T50)*מקרא!$B$11,"")) | AB50: 31.32685 | AC50: 34.61107 | AD50: מפה | AE50: Waze
A51: 50 | B51: =IF(C51="",IF(D51="",I51,"החווה של "&D51),IF(D51="",C51,C51&" - החווה של "&D51)) -> פטיש | I51: פטיש | J51: 749 | K51: מושב | L51: מרחבים | M51: הנגב | N51: 08-9929444 | R51: 3250 | V51: =IF(AND(S51="",T51=""),"",IFERROR(N(S51)*מקרא!$B$10+N(T51)*מקרא!$B$11,"")) | AB51: 31.32733 | AC51: 34.56001 | AD51: מפה | AE51: Waze
A52: 51 | B52: =IF(C52="",IF(D52="",I52,"החווה של "&D52),IF(D52="",C52,C52&" - החווה של "&D52)) -> פעמי תש"ז | I52: פעמי תש"ז | J52: 2059 | K52: מושב | L52: מרחבים | M52: הנגב | N52: 08-9929444 | R52: 3250 | V52: =IF(AND(S52="",T52=""),"",IFERROR(N(S52)*מקרא!$B$10+N(T52)*מקרא!$B$11,"")) | AB52: 31.43912 | AC52: 34.69273 | AD52: מפה | AE52: Waze
A53: 52 | B53: =IF(C53="",IF(D53="",I53,"החווה של "&D53),IF(D53="",C53,C53&" - החווה של "&D53)) -> קלחים | I53: קלחים | J53: 414 | K53: מושב | L53: מרחבים | M53: הנגב | N53: 08-9929444 | R53: 3250 | V53: =IF(AND(S53="",T53=""),"",IFERROR(N(S53)*מקרא!$B$10+N(T53)*מקרא!$B$11,"")) | AB53: 31.44935 | AC53: 34.67784 | AD53: מפה | AE53: Waze
A54: 53 | B54: =IF(C54="",IF(D54="",I54,"החווה של "&D54),IF(D54="",C54,C54&" - החווה של "&D54)) -> רנן | I54: רנן | J54: 789 | K54: מושב | L54: מרחבים | M54: הנגב | N54: 08-9929444 | R54: 3250 | V54: =IF(AND(S54="",T54=""),"",IFERROR(N(S54)*מקרא!$B$10+N(T54)*מקרא!$B$11,"")) | AB54: 31.33799 | AC54: 34.60133 | AD54: מפה | AE54: Waze
A55: 54 | B55: =IF(C55="",IF(D55="",I55,"החווה של "&D55),IF(D55="",C55,C55&" - החווה של "&D55)) -> שדה צבי | I55: שדה צבי | J55: 2049 | K55: מושב | L55: מרחבים | M55: הנגב | N55: 08-9929444 | R55: 3250 | V55: =IF(AND(S55="",T55=""),"",IFERROR(N(S55)*מקרא!$B$10+N(T55)*מקרא!$B$11,"")) | AB55: 31.44876 | AC55: 34.71224 | AD55: מפה | AE55: Waze
... A87: 86 | B87: =IF(C87="",IF(D87="",I87,"החווה של "&D87),IF(D87="",C87,C87&" - החווה של "&D87)) -> תושיה | I87: תושיה | J87: 1083 | K87: יישוב קהילתי | L87: שדות נגב | M87: הנגב | N87: 08-9938933 | R87: 700 | V87: =IF(AND(S87="",T87=""),"",IFERROR(N(S87)*מקרא!$B$10+N(T87)*מקרא!$B$11,"")) | AB87: 31.43374 | AC87: 34.54087 | AD87: מפה | AE87: Waze
A88: 87 | B88: =IF(C88="",IF(D88="",I88,"החווה של "&D88),IF(D88="",C88,C88&" - החווה של "&D88)) -> אור הנר | I88: אור הנר | J88: 67 | K88: קיבוץ | L88: שער הנגב | M88: הנגב | N88: 08-6806225 | R88: 9000 | V88: =IF(AND(S88="",T88=""),"",IFERROR(N(S88)*מקרא!$B$10+N(T88)*מקרא!$B$11,"")) | AB88: 31.55704 | AC88: 34.59951 | AD88: מפה | AE88: Waze | AF88: מועצת עוטף עזה
A89: 88 | B89: =IF(C89="",IF(D89="",I89,"החווה של "&D89),IF(D89="",C89,C89&" - החווה של "&D89)) -> ארז | I89: ארז | J89: 714 | K89: קיבוץ | L89: שער הנגב | M89: הנגב | N89: 08-6806225 | R89: 9000 | V89: =IF(AND(S89="",T89=""),"",IFERROR(N(S89)*מקרא!$B$10+N(T89)*מקרא!$B$11,"")) | AB89: 31.56022 | AC89: 34.56642 | AD89: מפה | AE89: Waze | AF89: מועצת עוטף עזה
A90: 89 | B90: =IF(C90="",IF(D90="",I90,"החווה של "&D90),IF(D90="",C90,C90&" - החווה של "&D90)) -> ברור חיל | I90: ברור חיל | J90: 428 | K90: קיבוץ | L90: שער הנגב | M90: הנגב | N90: 08-6806225 | R90: 9000 | V90: =IF(AND(S90="",T90=""),"",IFERROR(N(S90)*מקרא!$B$10+N(T90)*מקרא!$B$11,"")) | AB90: 31.5578 | AC90: 34.64669 | AD90: מפה | AE90: Waze | AF90: מועצת עוטף עזה
...

Sheet רשימות
A1: סוג הישות המשפטית | B1: סוג פעילות | C1: הסכם רעיה/חכירה | D1: סטטוס | E1: עדיפות
A2: חקלאי פרטי | B2: מעובד | C2: חוזה חכירה לדורות | D2: לא נוצר קשר | E2: 1
A3: אגודה שיתופית | B3: מרעה | C3: חוזה שכירות משבצת (תלת-צדדי) | D3: ליצירת קשר | E3: 2
A4: גד״ש | B4: מעורב | C4: הסכם הרשאה לרעייה | D4: נוצר קשר | E4: 3
A5: שח״ם | B5: לא ידוע | C5: הסכם הרשאה זמני | D5: בוקרה
A6: קיבוץ | C6: הצהרת חקלאים בלבד | D6: הסכמה נחתמה
A7: מושב | C7: אין מסמך | D7: לא רלוונטי
A8: רועה/בעל עדר | C8: לא ידוע
A9: לא ידוע
A12: ניתן להוסיף ערכים בהמשך כל עמודה — יופיעו אוטומטית ברשימות.
